Workbook

Sheet Raw Data
A1: OrderID | B1: CustomerName | C1: Region | D1: Product | E1: Quantity | F1: UnitPrice | G1: OrderDate
A2: 4001 | B2: Amit Sharma | C2: North | D2: Notebook | E2: 10 | F2: 50 | G2: 45292
A3: 4002 | B3: Neha Verma | C3: South | D3: Pen | E3: 20 | F3: 10 | G3: 45323
A4: 4003 | B4: Rahul Singh | C4: East | D4: Marker | E4: 15 | F4: 25 | G4: 45352
A5: 4004 | B5: Pooja Mehta | C5: West | D5: Notebook | E5: 5 | F5: 50 | G5: 45383
A6: 4005 | B6: Ankit Jain | C6: North | D6: Pencil | E6: 30 | F6: 5 | G6: 45413
A7: 4006 | B7: Sneha Patel | C7: South | D7: Notebook | E7: 12 | F7: 50 | G7: 45444
A8: 4007 | B8: Vikas Gupta | C8: East | D8: Eraser | E8: 25 | F8: 8 | G8: 45474
A9: 4008 | B9: Meera Nair | C9: West | D9: Pen | E9: 18 | F9: 10 | G9: 45505
A10: 4009 | B10: Anjali Rao | C10: North | D10: Marker | E10: 22 | F10: 25 | G10: 45536
A11: 4010 | B11: Manoj Das | C11: South | D11: Notebook | E11: 8 | F11: 50 | G11: 45566
A12: 4011 | B12: Ritika Sen | C12: East | D12: Pencil | E12: 40 | F12: 5 | G12: 45597
A13: 4012 | B13: Karan Malhotra | C13: West | D13: Eraser | E13: 35 | F13: 8 | G13: 45627
A14: 4013 | B14: Aryan Joshi | C14: North | D14: Notebook | E14: 14 | F14: 50 | G14: 13-01-2024
A15: 4014 | B15: Divya Kapoor | C15: South | D15: Pen | E15: 28 | F15: 10 | G15: 14-01-2024
A16: 4015 | B16: Sahil Arora | C16: East | D16: Marker | E16: 12 | F16: 25 | G16: 15-01-2024
A17: 4016 | B17: Muskan Jain | C17: West | D17: Pencil | E17: 25 | F17: 5 | G17: 16-01-2024
A18: 4017 | B18: Rohan Gupta | C18: North | D18: Eraser | E18: 20 | F18: 8 | G18: 17-01-2024
A19: 4018 | B19: Nidhi Sharma | C19: South | D19: Notebook | E19: 10 | F19: 50 | G19: 18-01-2024
A20: 4019 | B20: Tarun Verma | C20: East | D20: Pen | E20: 15 | F20: 10 | G20: 19-01-2024
A21: 4020 | B21: Simran Kaur | C21: West | D21: Marker | E21: 18 | F21: 25 | G21: 20-01-2024
A22: 4021 | B22: Deepak Rao | C22: North | D22: Notebook | E22: 9 | F22: 50 | G22: 21-01-2024
A23: 4022 | B23: Payal Mehta | C23: South | D23: Pencil | E23: 35 | F23: 5 | G23: 22-01-2024
A24: 4023 | B24: Aditya Singh | C24: East | D24: Eraser | E24: 30 | F24: 8 | G24: 23-01-2024
A25: 4024 | B25: Shreya Nair | C25: West | D25: Notebook | E25: 11 | F25: 50 | G25: 24-01-2024
... A32: 4031 | B32: Harsh Yadav | C32: East | D32: Marker | E32: 10 | F32: 25 | G32: 31-01-2024
A33: 4032 | B33: Kajal Rani | C33: West | D33: Pencil | E33: 18 | F33: 5 | G33: 45293
A34: 4033 | B34: Varun Sharma | C34: North | D34: Eraser | E34: 22 | F34: 8 | G34: 45324
A35: 4034 | B35: Swati Arora | C35: South | D35: Notebook | E35: 17 | F35: 50 | G35: 45353
A36: 4035 | B36: Akhil Jain | C36: East | D36: Pen | E36: 19 | F36: 10 | G36: 45384
A37: 4036 | B37: Priyanka Das | C37: West | D37: Marker | E37: 15 | F37: 25 | G37: 45414
A38: 4037 | B38: Ravi Nair | C38: North | D38: Pencil | E38: 28 | F38: 5 | G38: 45445
A39: 4038 | B39: Komal Singh | C39: South | D39: Eraser | E39: 24 | F39: 8 | G39: 45475
A40: 4039 | B40: Ayesha Khan | C40: East | D40: Notebook | E40: 16 | F40: 50 | G40: 45506
A41: 4040 | B41: Arjun Mehta | C41: West | D41: Pen | E41: 27 | F41: 10 | G41: 45537
A42: 4041 | B42: Sonali Gupta | C42: North | D42: Marker | E42: 21 | F42: 25 | G42: 45567
A43: 4042 | B43: Neeraj Kapoor | C43: South | D43: Pencil | E43: 30 | F43: 5 | G43: 45598
A44: 4043 | B44: Shruti Sharma | C44: East | D44: Eraser | E44: 26 | F44: 8 | G44: 45628
A45: 4044 | B45: Yash Arora | C45: West | D45: Notebook | E45: 14 | F45: 50 | G45: 13-02-2024
A46: 4045 | B46: Manish Das | C46: North | D46: Pen | E46: 20 | F46: 10 | G46: 14-02-2024
...

Sheet Dataset
A1: OrderID | B1: CustomerName | C1: Region | D1: Product | E1: Quantity | F1: UnitPrice | G1: OrderDate
A2: 4001 | B2: Amit Sharma | C2: North | D2: Notebook | E2: 10 | F2: 50 | G2: 45292
A3: 4002 | B3: Neha Verma | C3: South | D3: Pen | E3: 20 | F3: 10 | G3: 45323
A4: 4003 | B4: Rahul Singh | C4: East | D4: Marker | E4: 15 | F4: 25 | G4: 45352
A5: 4004 | B5: Pooja Mehta | C5: West | D5: Notebook | E5: 5 | F5: 50 | G5: 45383
A6: 4005 | B6: Ankit Jain | C6: North | D6: Pencil | E6: 30 | F6: 5 | G6: 45413
A7: 4006 | B7: Sneha Patel | C7: South | D7: Notebook | E7: 12 | F7: 50 | G7: 45444
A8: 4007 | B8: Vikas Gupta | C8: East | D8: Eraser | E8: 25 | F8: 8 | G8: 45474
A9: 4008 | B9: Meera Nair | C9: West | D9: Pen | E9: 18 | F9: 10 | G9: 45505
A10: 4009 | B10: Anjali Rao | C10: North | D10: Marker | E10: 22 | F10: 25 | G10: 45536
A11: 4010 | B11: Manoj Das | C11: South | D11: Notebook | E11: 8 | F11: 50 | G11: 45566
A12: 4011 | B12: Ritika Sen | C12: East | D12: Pencil | E12: 40 | F12: 5 | G12: 45597
A13: 4012 | B13: Karan Malhotra | C13: West | D13: Eraser | E13: 35 | F13: 8 | G13: 45627
A14: 4013 | B14: Aryan Joshi | C14: North | D14: Notebook | E14: 14 | F14: 50 | G14: 13-01-2024
A15: 4014 | B15: Divya Kapoor | C15: South | D15: Pen | E15: 28 | F15: 10 | G15: 14-01-2024
A16: 4015 | B16: Sahil Arora | C16: East | D16: Marker | E16: 12 | F16: 25 | G16: 15-01-2024
A17: 4016 | B17: Muskan Jain | C17: West | D17: Pencil | E17: 25 | F17: 5 | G17: 16-01-2024
A18: 4017 | B18: Rohan Gupta | C18: North | D18: Eraser | E18: 20 | F18: 8 | G18: 17-01-2024
A19: 4018 | B19: Nidhi Sharma | C19: South | D19: Notebook | E19: 10 | F19: 50 | G19: 18-01-2024
A20: 4019 | B20: Tarun Verma | C20: East | D20: Pen | E20: 15 | F20: 10 | G20: 19-01-2024
A21: 4020 | B21: Simran Kaur | C21: West | D21: Marker | E21: 18 | F21: 25 | G21: 20-01-2024
A22: 4021 | B22: Deepak Rao | C22: North | D22: Notebook | E22: 9 | F22: 50 | G22: 21-01-2024
A23: 4022 | B23: Payal Mehta | C23: South | D23: Pencil | E23: 35 | F23: 5 | G23: 22-01-2024
A24: 4023 | B24: Aditya Singh | C24: East | D24: Eraser | E24: 30 | F24: 8 | G24: 23-01-2024
A25: 4024 | B25: Shreya Nair | C25: West | D25: Notebook | E25: 11 | F25: 50 | G25: 24-01-2024
... A32: 4031 | B32: Harsh Yadav | C32: East | D32: Marker | E32: 10 | F32: 25 | G32: 31-01-2024
A33: 4032 | B33: Kajal Rani | C33: West | D33: Pencil | E33: 18 | F33: 5 | G33: 45293
A34: 4033 | B34: Varun Sharma | C34: North | D34: Eraser | E34: 22 | F34: 8 | G34: 45324
A35: 4034 | B35: Swati Arora | C35: South | D35: Notebook | E35: 17 | F35: 50 | G35: 45353
A36: 4035 | B36: Akhil Jain | C36: East | D36: Pen | E36: 19 | F36: 10 | G36: 45384
A37: 4036 | B37: Priyanka Das | C37: West | D37: Marker | E37: 15 | F37: 25 | G37: 45414
A38: 4037 | B38: Ravi Nair | C38: North | D38: Pencil | E38: 28 | F38: 5 | G38: 45445
A39: 4038 | B39: Komal Singh | C39: South | D39: Eraser | E39: 24 | F39: 8 | G39: 45475
A40: 4039 | B40: Ayesha Khan | C40: East | D40: Notebook | E40: 16 | F40: 50 | G40: 45506
A41: 4040 | B41: Arjun Mehta | C41: West | D41: Pen | E41: 27 | F41: 10 | G41: 45537
A42: 4041 | B42: Sonali Gupta | C42: North | D42: Marker | E42: 21 | F42: 25 | G42: 45567
A43: 4042 | B43: Neeraj Kapoor | C43: South | D43: Pencil | E43: 30 | F43: 5 | G43: 45598
A44: 4043 | B44: Shruti Sharma | C44: East | D44: Eraser | E44: 26 | F44: 8 | G44: 45628
A45: 4044 | B45: Yash Arora | C45: West | D45: Notebook | E45: 14 | F45: 50 | G45: 13-02-2024
A46: 4045 | B46: Manish Das | C46: North | D46: Pen | E46: 20 | F46: 10 | G46: 14-02-2024
...

Sheet Task 1 Total Sales
A1: OrderID | B1: CustomerName | C1: Region | D1: Product | E1: Quantity | F1: UnitPrice | G1: OrderDate | H1: Total Sales
A2: 4001 | B2: Amit Sharma | C2: North | D2: Notebook | E2: 10 | F2: 50 | G2: 45292 | H2: =E2*F2 -> 500
A3: 4002 | B3: Neha Verma | C3: South | D3: Pen | E3: 20 | F3: 10 | G3: 45323 | H3: =E3*F3 -> 200
A4: 4003 | B4: Rahul Singh | C4: East | D4: Marker | E4: 15 | F4: 25 | G4: 45352 | H4: =E4*F4 -> 375
A5: 4004 | B5: Pooja Mehta | C5: West | D5: Notebook | E5: 5 | F5: 50 | G5: 45383 | H5: =E5*F5 -> 250
A6: 4005 | B6: Ankit Jain | C6: North | D6: Pencil | E6: 30 | F6: 5 | G6: 45413 | H6: =E6*F6 -> 150
A7: 4006 | B7: Sneha Patel | C7: South | D7: Notebook | E7: 12 | F7: 50 | G7: 45444 | H7: =E7*F7 -> 600
A8: 4007 | B8: Vikas Gupta | C8: East | D8: Eraser | E8: 25 | F8: 8 | G8: 45474 | H8: =E8*F8 -> 200
A9: 4008 | B9: Meera Nair | C9: West | D9: Pen | E9: 18 | F9: 10 | G9: 45505 | H9: =E9*F9 -> 180
A10: 4009 | B10: Anjali Rao | C10: North | D10: Marker | E10: 22 | F10: 25 | G10: 45536 | H10: =E10*F10 -> 550
A11: 4010 | B11: Manoj Das | C11: South | D11: Notebook | E11: 8 | F11: 50 | G11: 45566 | H11: =E11*F11 -> 400
A12: 4011 | B12: Ritika Sen | C12: East | D12: Pencil | E12: 40 | F12: 5 | G12: 45597 | H12: =E12*F12 -> 200
A13: 4012 | B13: Karan Malhotra | C13: West | D13: Eraser | E13: 35 | F13: 8 | G13: 45627 | H13: =E13*F13 -> 280
A14: 4013 | B14: Aryan Joshi | C14: North | D14: Notebook | E14: 14 | F14: 50 | G14: 13-01-2024 | H14: =E14*F14 -> 700
A15: 4014 | B15: Divya Kapoor | C15: South | D15: Pen | E15: 28 | F15: 10 | G15: 14-01-2024 | H15: =E15*F15 -> 280
A16: 4015 | B16: Sahil Arora | C16: East | D16: Marker | E16: 12 | F16: 25 | G16: 15-01-2024 | H16: =E16*F16 -> 300
A17: 4016 | B17: Muskan Jain | C17: West | D17: Pencil | E17: 25 | F17: 5 | G17: 16-01-2024 | H17: =E17*F17 -> 125
A18: 4017 | B18: Rohan Gupta | C18: North | D18: Eraser | E18: 20 | F18: 8 | G18: 17-01-2024 | H18: =E18*F18 -> 160
A19: 4018 | B19: Nidhi Sharma | C19: South | D19: Notebook | E19: 10 | F19: 50 | G19: 18-01-2024 | H19: =E19*F19 -> 500
A20: 4019 | B20: Tarun Verma | C20: East | D20: Pen | E20: 15 | F20: 10 | G20: 19-01-2024 | H20: =E20*F20 -> 150
A21: 4020 | B21: Simran Kaur | C21: West | D21: Marker | E21: 18 | F21: 25 | G21: 20-01-2024 | H21: =E21*F21 -> 450
A22: 4021 | B22: Deepak Rao | C22: North | D22: Notebook | E22: 9 | F22: 50 | G22: 21-01-2024 | H22: =E22*F22 -> 450
A23: 4022 | B23: Payal Mehta | C23: South | D23: Pencil | E23: 35 | F23: 5 | G23: 22-01-2024 | H23: =E23*F23 -> 175
A24: 4023 | B24: Aditya Singh | C24: East | D24: Eraser | E24: 30 | F24: 8 | G24: 23-01-2024 | H24: =E24*F24 -> 240
A25: 4024 | B25: Shreya Nair | C25: West | D25: Notebook | E25: 11 | F25: 50 | G25: 24-01-2024 | H25: =E25*F25 -> 550
... A32: 4031 | B32: Harsh Yadav | C32: East | D32: Marker | E32: 10 | F32: 25 | G32: 31-01-2024 | H32: =E32*F32 -> 250
A33: 4032 | B33: Kajal Rani | C33: West | D33: Pencil | E33: 18 | F33: 5 | G33: 45293 | H33: =E33*F33 -> 90
A34: 4033 | B34: Varun Sharma | C34: North | D34: Eraser | E34: 22 | F34: 8 | G34: 45324 | H34: =E34*F34 -> 176
A35: 4034 | B35: Swati Arora | C35: South | D35: Notebook | E35: 17 | F35: 50 | G35: 45353 | H35: =E35*F35 -> 850
A36: 4035 | B36: Akhil Jain | C36: East | D36: Pen | E36: 19 | F36: 10 | G36: 45384 | H36: =E36*F36 -> 190
A37: 4036 | B37: Priyanka Das | C37: West | D37: Marker | E37: 15 | F37: 25 | G37: 45414 | H37: =E37*F37 -> 375
A38: 4037 | B38: Ravi Nair | C38: North | D38: Pencil | E38: 28 | F38: 5 | G38: 45445 | H38: =E38*F38 -> 140
A39: 4038 | B39: Komal Singh | C39: South | D39: Eraser | E39: 24 | F39: 8 | G39: 45475 | H39: =E39*F39 -> 192
A40: 4039 | B40: Ayesha Khan | C40: East | D40: Notebook | E40: 16 | F40: 50 | G40: 45506 | H40: =E40*F40 -> 800
A41: 4040 | B41: Arjun Mehta | C41: West | D41: Pen | E41: 27 | F41: 10 | G41: 45537 | H41: =E41*F41 -> 270
A42: 4041 | B42: Sonali Gupta | C42: North | D42: Marker | E42: 21 | F42: 25 | G42: 45567 | H42: =E42*F42 -> 525
A43: 4042 | B43: Neeraj Kapoor | C43: South | D43: Pencil | E43: 30 | F43: 5 | G43: 45598 | H43: =E43*F43 -> 150
A44: 4043 | B44: Shruti Sharma | C44: East | D44: Eraser | E44: 26 | F44: 8 | G44: 45628 | H44: =E44*F44 -> 208
A45: 4044 | B45: Yash Arora | C45: West | D45: Notebook | E45: 14 | F45: 50 | G45: 13-02-2024 | H45: =E45*F45 -> 700
A46: 4045 | B46: Manish Das | C46: North | D46: Pen | E46: 20 | F46: 10 | G46: 14-02-2024 | H46: =E46*F46 -> 200
...

Sheet Task 2 Data Formatting
A1: OrderID | B1: CustomerName | C1: Region | D1: Product | E1: Quantity | F1: UnitPrice | G1: OrderDate | H1: Total Sales
A2: 4001 | B2: Amit Sharma | C2: North | D2: Notebook | E2: 10 | F2: 50 | G2: 45292 | H2: =E2*F2 -> 500
A3: 4002 | B3: Neha Verma | C3: South | D3: Pen | E3: 20 | F3: 10 | G3: 45323 | H3: =E3*F3 -> 200
A4: 4003 | B4: Rahul Singh | C4: East | D4: Marker | E4: 15 | F4: 25 | G4: 45352 | H4: =E4*F4 -> 375
A5: 4004 | B5: Pooja Mehta | C5: West | D5: Notebook | E5: 5 | F5: 50 | G5: 45383 | H5: =E5*F5 -> 250
A6: 4005 | B6: Ankit Jain | C6: North | D6: Pencil | E6: 30 | F6: 5 | G6: 45413 | H6: =E6*F6 -> 150
A7: 4006 | B7: Sneha Patel | C7: South | D7: Notebook | E7: 12 | F7: 50 | G7: 45444 | H7: =E7*F7 -> 600
A8: 4007 | B8: Vikas Gupta | C8: East | D8: Eraser | E8: 25 | F8: 8 | G8: 45474 | H8: =E8*F8 -> 200
A9: 4008 | B9: Meera Nair | C9: West | D9: Pen | E9: 18 | F9: 10 | G9: 45505 | H9: =E9*F9 -> 180
A10: 4009 | B10: Anjali Rao | C10: North | D10: Marker | E10: 22 | F10: 25 | G10: 45536 | H10: =E10*F10 -> 550
A11: 4010 | B11: Manoj Das | C11: South | D11: Notebook | E11: 8 | F11: 50 | G11: 45566 | H11: =E11*F11 -> 400
A12: 4011 | B12: Ritika Sen | C12: East | D12: Pencil | E12: 40 | F12: 5 | G12: 45597 | H12: =E12*F12 -> 200
A13: 4012 | B13: Karan Malhotra | C13: West | D13: Eraser | E13: 35 | F13: 8 | G13: 45627 | H13: =E13*F13 -> 280
A14: 4013 | B14: Aryan Joshi | C14: North | D14: Notebook | E14: 14 | F14: 50 | G14: 13-01-2024 | H14: =E14*F14 -> 700
A15: 4014 | B15: Divya Kapoor | C15: South | D15: Pen | E15: 28 | F15: 10 | G15: 14-01-2024 | H15: =E15*F15 -> 280
A16: 4015 | B16: Sahil Arora | C16: East | D16: Marker | E16: 12 | F16: 25 | G16: 15-01-2024 | H16: =E16*F16 -> 300
A17: 4016 | B17: Muskan Jain | C17: West | D17: Pencil | E17: 25 | F17: 5 | G17: 16-01-2024 | H17: =E17*F17 -> 125
A18: 4017 | B18: Rohan Gupta | C18: North | D18: Eraser | E18: 20 | F18: 8 | G18: 17-01-2024 | H18: =E18*F18 -> 160
A19: 4018 | B19: Nidhi Sharma | C19: South | D19: Notebook | E19: 10 | F19: 50 | G19: 18-01-2024 | H19: =E19*F19 -> 500
A20: 4019 | B20: Tarun Verma | C20: East | D20: Pen | E20: 15 | F20: 10 | G20: 19-01-2024 | H20: =E20*F20 -> 150
A21: 4020 | B21: Simran Kaur | C21: West | D21: Marker | E21: 18 | F21: 25 | G21: 20-01-2024 | H21: =E21*F21 -> 450
A22: 4021 | B22: Deepak Rao | C22: North | D22: Notebook | E22: 9 | F22: 50 | G22: 21-01-2024 | H22: =E22*F22 -> 450
A23: 4022 | B23: Payal Mehta | C23: South | D23: Pencil | E23: 35 | F23: 5 | G23: 22-01-2024 | H23: =E23*F23 -> 175
A24: 4023 | B24: Aditya Singh | C24: East | D24: Eraser | E24: 30 | F24: 8 | G24: 23-01-2024 | H24: =E24*F24 -> 240
A25: 4024 | B25: Shreya Nair | C25: West | D25: Notebook | E25: 11 | F25: 50 | G25: 24-01-2024 | H25: =E25*F25 -> 550
... A32: 4031 | B32: Harsh Yadav | C32: East | D32: Marker | E32: 10 | F32: 25 | G32: 31-01-2024 | H32: =E32*F32 -> 250
A33: 4032 | B33: Kajal Rani | C33: West | D33: Pencil | E33: 18 | F33: 5 | G33: 45293 | H33: =E33*F33 -> 90
A34: 4033 | B34: Varun Sharma | C34: North | D34: Eraser | E34: 22 | F34: 8 | G34: 45324 | H34: =E34*F34 -> 176
A35: 4034 | B35: Swati Arora | C35: South | D35: Notebook | E35: 17 | F35: 50 | G35: 45353 | H35: =E35*F35 -> 850
A36: 4035 | B36: Akhil Jain | C36: East | D36: Pen | E36: 19 | F36: 10 | G36: 45384 | H36: =E36*F36 -> 190
A37: 4036 | B37: Priyanka Das | C37: West | D37: Marker | E37: 15 | F37: 25 | G37: 45414 | H37: =E37*F37 -> 375
A38: 4037 | B38: Ravi Nair | C38: North | D38: Pencil | E38: 28 | F38: 5 | G38: 45445 | H38: =E38*F38 -> 140
A39: 4038 | B39: Komal Singh | C39: South | D39: Eraser | E39: 24 | F39: 8 | G39: 45475 | H39: =E39*F39 -> 192
A40: 4039 | B40: Ayesha Khan | C40: East | D40: Notebook | E40: 16 | F40: 50 | G40: 45506 | H40: =E40*F40 -> 800
A41: 4040 | B41: Arjun Mehta | C41: West | D41: Pen | E41: 27 | F41: 10 | G41: 45537 | H41: =E41*F41 -> 270
A42: 4041 | B42: Sonali Gupta | C42: North | D42: Marker | E42: 21 | F42: 25 | G42: 45567 | H42: =E42*F42 -> 525
A43: 4042 | B43: Neeraj Kapoor | C43: South | D43: Pencil | E43: 30 | F43: 5 | G43: 45598 | H43: =E43*F43 -> 150
A44: 4043 | B44: Shruti Sharma | C44: East | D44: Eraser | E44: 26 | F44: 8 | G44: 45628 | H44: =E44*F44 -> 208
A45: 4044 | B45: Yash Arora | C45: West | D45: Notebook | E45: 14 | F45: 50 | G45: 13-02-2024 | H45: =E45*F45 -> 700
A46: 4045 | B46: Manish Das | C46: North | D46: Pen | E46: 20 | F46: 10 | G46: 14-02-2024 | H46: =E46*F46 -> 200
...

Sheet Task 3 Summary Calculations
B2: Summary Section
B3: Total Quantity Sold | C3: =SUM('Task 1 Total Sales'!E2:E71) -> 1430
B4: Average Quantity | C4: =AVERAGE('Task 1 Total Sales'!E2:E71) -> 20.428571
B5: Maximum Quantity | C5: =MAX('Task 1 Total Sales'!E2:E71) -> 40
B6: Minimum Quantity | C6: =MIN('Task 1 Total Sales'!E2:E71) -> 5

Sheet Task 5 Filtered Data
A1: OrderID | B1: CustomerName | C1: Region | D1: Product | E1: Quantity | F1: UnitPrice | G1: OrderDate
A2: 4001 | B2: Amit Sharma | C2: North | D2: Notebook | E2: 10 | F2: 50 | G2: 45292
A3: 4002 | B3: Neha Verma | C3: South | D3: Pen | E3: 20 | F3: 10 | G3: 45323
A4: 4003 | B4: Rahul Singh | C4: East | D4: Marker | E4: 15 | F4: 25 | G4: 45352
A5: 4004 | B5: Pooja Mehta | C5: West | D5: Notebook | E5: 5 | F5: 50 | G5: 45383
A6: 4005 | B6: Ankit Jain | C6: North | D6: Pencil | E6: 30 | F6: 5 | G6: 45413
A7: 4006 | B7: Sneha Patel | C7: South | D7: Notebook | E7: 12 | F7: 50 | G7: 45444
A8: 4007 | B8: Vikas Gupta | C8: East | D8: Eraser | E8: 25 | F8: 8 | G8: 45474
A9: 4008 | B9: Meera Nair | C9: West | D9: Pen | E9: 18 | F9: 10 | G9: 45505
A10: 4009 | B10: Anjali Rao | C10: North | D10: Marker | E10: 22 | F10: 25 | G10: 45536
A11: 4010 | B11: Manoj Das | C11: South | D11: Notebook | E11: 8 | F11: 50 | G11: 45566
A12: 4011 | B12: Ritika Sen | C12: East | D12: Pencil | E12: 40 | F12: 5 | G12: 45597
A13: 4012 | B13: Karan Malhotra | C13: West | D13: Eraser | E13: 35 | F13: 8 | G13: 45627
A14: 4013 | B14: Aryan Joshi | C14: North | D14: Notebook | E14: 14 | F14: 50 | G14: 13-01-2024
A15: 4014 | B15: Divya Kapoor | C15: South | D15: Pen | E15: 28 | F15: 10 | G15: 14-01-2024
A16: 4015 | B16: Sahil Arora | C16: East | D16: Marker | E16: 12 | F16: 25 | G16: 15-01-2024
A17: 4016 | B17: Muskan Jain | C17: West | D17: Pencil | E17: 25 | F17: 5 | G17: 16-01-2024
A18: 4017 | B18: Rohan Gupta | C18: North | D18: Eraser | E18: 20 | F18: 8 | G18: 17-01-2024
A19: 4018 | B19: Nidhi Sharma | C19: South | D19: Notebook | E19: 10 | F19: 50 | G19: 18-01-2024
A20: 4019 | B20: Tarun Verma | C20: East | D20: Pen | E20: 15 | F20: 10 | G20: 19-01-2024
A21: 4020 | B21: Simran Kaur | C21: West | D21: Marker | E21: 18 | F21: 25 | G21: 20-01-2024
A22: 4021 | B22: Deepak Rao | C22: North | D22: Notebook | E22: 9 | F22: 50 | G22: 21-01-2024
A23: 4022 | B23: Payal Mehta | C23: South | D23: Pencil | E23: 35 | F23: 5 | G23: 22-01-2024
A24: 4023 | B24: Aditya Singh | C24: East | D24: Eraser | E24: 30 | F24: 8 | G24: 23-01-2024
A25: 4024 | B25: Shreya Nair | C25: West | D25: Notebook | E25: 11 | F25: 50 | G25: 24-01-2024
... A32: 4031 | B32: Harsh Yadav | C32: East | D32: Marker | E32: 10 | F32: 25 | G32: 31-01-2024
A33: 4032 | B33: Kajal Rani | C33: West | D33: Pencil | E33: 18 | F33: 5 | G33: 45293
A34: 4033 | B34: Varun Sharma | C34: North | D34: Eraser | E34: 22 | F34: 8 | G34: 45324
A35: 4034 | B35: Swati Arora | C35: South | D35: Notebook | E35: 17 | F35: 50 | G35: 45353
A36: 4035 | B36: Akhil Jain | C36: East | D36: Pen | E36: 19 | F36: 10 | G36: 45384
A37: 4036 | B37: Priyanka Das | C37: West | D37: Marker | E37: 15 | F37: 25 | G37: 45414
A38: 4037 | B38: Ravi Nair | C38: North | D38: Pencil | E38: 28 | F38: 5 | G38: 45445
A39: 4038 | B39: Komal Singh | C39: South | D39: Eraser | E39: 24 | F39: 8 | G39: 45475
A40: 4039 | B40: Ayesha Khan | C40: East | D40: Notebook | E40: 16 | F40: 50 | G40: 45506
A41: 4040 | B41: Arjun Mehta | C41: West | D41: Pen | E41: 27 | F41: 10 | G41: 45537
A42: 4041 | B42: Sonali Gupta | C42: North | D42: Marker | E42: 21 | F42: 25 | G42: 45567
A43: 4042 | B43: Neeraj Kapoor | C43: South | D43: Pencil | E43: 30 | F43: 5 | G43: 45598
A44: 4043 | B44: Shruti Sharma | C44: East | D44: Eraser | E44: 26 | F44: 8 | G44: 45628
A45: 4044 | B45: Yash Arora | C45: West | D45: Notebook | E45: 14 | F45: 50 | G45: 13-02-2024
A46: 4045 | B46: Manish Das | C46: North | D46: Pen | E46: 20 | F46: 10 | G46: 14-02-2024
...

Sheet Task 4 Sorted Data
A1: OrderID | B1: CustomerName | C1: Region | D1: Product | E1: Quantity | F1: UnitPrice | G1: OrderDate
A2: 4007 | B2: Vikas Gupta | C2: East | D2: Eraser | E2: 25 | F2: 8 | G2: 45474
A3: 4023 | B3: Aditya Singh | C3: East | D3: Eraser | E3: 30 | F3: 8 | G3: 23-01-2024
A4: 4043 | B4: Shruti Sharma | C4: East | D4: Eraser | E4: 26 | F4: 8 | G4: 45628
A5: 4065 | B5: Sahil Arora | C5: East | D5: Eraser | E5: 26 | F5: 8 | G5: 45415
A6: 4003 | B6: Rahul Singh | C6: East | D6: Marker | E6: 15 | F6: 25 | G6: 45352
A7: 4015 | B7: Sahil Arora | C7: East | D7: Marker | E7: 12 | F7: 25 | G7: 15-01-2024
A8: 4031 | B8: Harsh Yadav | C8: East | D8: Marker | E8: 10 | F8: 25 | G8: 31-01-2024
A9: 4039 | B9: Ayesha Khan | C9: East | D9: Notebook | E9: 16 | F9: 50 | G9: 45506
A10: 4057 | B10: Vikas Gupta | C10: East | D10: Notebook | E10: 20 | F10: 50 | G10: 26-02-2024
A11: 4061 | B11: Ritika Sen | C11: East | D11: Notebook | E11: 12 | F11: 50 | G11: 45294
A12: 4019 | B12: Tarun Verma | C12: East | D12: Pen | E12: 15 | F12: 10 | G12: 19-01-2024
A13: 4035 | B13: Akhil Jain | C13: East | D13: Pen | E13: 19 | F13: 10 | G13: 45384
A14: 4053 | B14: Rahul Singh | C14: East | D14: Pen | E14: 22 | F14: 10 | G14: 22-02-2024
A15: 4011 | B15: Ritika Sen | C15: East | D15: Pencil | E15: 40 | F15: 5 | G15: 45597
A16: 4027 | B16: Rajesh Patel | C16: East | D16: Pencil | E16: 22 | F16: 5 | G16: 27-01-2024
A17: 4047 | B17: Sonia Verma | C17: East | D17: Pencil | E17: 19 | F17: 5 | G17: 16-02-2024
A18: 4069 | B18: Tarun Verma | C18: East | D18: Pencil | E18: 32 | F18: 5 | G18: 45538
A19: 4017 | B19: Rohan Gupta | C19: North | D19: Eraser | E19: 20 | F19: 8 | G19: 17-01-2024
A20: 4033 | B20: Varun Sharma | C20: North | D20: Eraser | E20: 22 | F20: 8 | G20: 45324
A21: 4055 | B21: Ankit Jain | C21: North | D21: Eraser | E21: 28 | F21: 8 | G21: 24-02-2024
A22: 4009 | B22: Anjali Rao | C22: North | D22: Marker | E22: 22 | F22: 25 | G22: 45536
A23: 4041 | B23: Sonali Gupta | C23: North | D23: Marker | E23: 21 | F23: 25 | G23: 45567
A24: 4051 | B24: Amit Sharma | C24: North | D24: Marker | E24: 18 | F24: 25 | G24: 20-02-2024
A25: 4067 | B25: Rohan Gupta | C25: North | D25: Marker | E25: 14 | F25: 25 | G25: 45476
A26: 4001 | B26: Amit Sharma | C26: North | D26: Notebook | E26: 10 | F26: 50 | G26: 45292
A27: 4013 | B27: Aryan Joshi | C27: North | D27: Notebook | E27: 14 | F27: 50 | G27: 13-01-2024
A28: 4021 | B28: Deepak Rao | C28: North | D28: Notebook | E28: 9 | F28: 50 | G28: 21-01-2024
A29: 4029 | B29: Anurag Mishra | C29: North | D29: Notebook | E29: 13 | F29: 50 | G29: 29-01-2024
A30: 4049 | B30: Ritika Jain | C30: North | D30: Notebook | E30: 12 | F30: 50 | G30: 18-02-2024
A31: 4025 | B31: Sanjay Kumar | C31: North | D31: Pen | E31: 14 | F31: 10 | G31: 25-01-2024
A32: 4045 | B32: Manish Das | C32: North | D32: Pen | E32: 20 | F32: 10 | G32: 14-02-2024
A33: 4063 | B33: Aryan Joshi | C33: North | D33: Pen | E33: 20 | F33: 10 | G33: 45354
A34: 4005 | B34: Ankit Jain | C34: North | D34: Pencil | E34: 30 | F34: 5 | G34: 45413
A35: 4037 | B35: Ravi Nair | C35: North | D35: Pencil | E35: 28 | F35: 5 | G35: 45445
A36: 4059 | B36: Anjali Rao | C36: North | D36: Pencil | E36: 24 | F36: 5 | G36: 28-02-2024
A37: 4038 | B37: Komal Singh | C37: South | D37: Eraser | E37: 24 | F37: 8 | G37: 45475
A38: 4060 | B38: Manoj Das | C38: South | D38: Eraser | E38: 30 | F38: 8 | G38: 29-02-2024
A39: 4026 | B39: Aarti Sharma | C39: South | D39: Marker | E39: 16 | F39: 25 | G39: 26-01-2024
A40: 4046 | B40: Rupal Nair | C40: South | D40: Marker | E40: 17 | F40: 25 | G40: 15-02-2024
...

Sheet Task 6 Counting Records
B2: Counting Records
B3: Total Number of orders | C3: =COUNT(Dataset!A2:A71) -> 70
B4: Number of orders in North Region | C4: =COUNTIF(Dataset!C2:C71,"North") -> 18
B5: Count Pen orders in South region | C5: =COUNTIFS(Dataset!C2:C71, "South", Dataset!D2:D71, "Pen") -> 5

Sheet Task 7 Region Wise Summary
A1: OrderID | B1: CustomerName | C1: Region | D1: Product | E1: Quantity | F1: UnitPrice | G1: OrderDate | H1: Total Sales
A2: 4001 | B2: Amit Sharma | C2: North | D2: Notebook | E2: 10 | F2: 50 | G2: 45292 | H2: =E2*F2 -> 500 | J2: Region | K2: Total Quantity | L2: Total Sales
A3: 4002 | B3: Neha Verma | C3: South | D3: Pen | E3: 20 | F3: 10 | G3: 45323 | H3: =E3*F3 -> 200 | J3: {=_xlfn.UNIQUE(C2:C71)} -> North | K3: =SUMIF(C2:C71, "North", (E2:E71)) -> 339 | L3: =SUMIF(C2:C71, "North", H2:H71) -> 6285
A4: 4003 | B4: Rahul Singh | C4: East | D4: Marker | E4: 15 | F4: 25 | G4: 45352 | H4: =E4*F4 -> 375 | J4: South | K4: =SUMIF(C3:C72, "South", (E3:E72)) -> 384 | L4: =SUMIF(C2:C71, "South", H2:H71) -> 6472
A5: 4004 | B5: Pooja Mehta | C5: West | D5: Notebook | E5: 5 | F5: 50 | G5: 45383 | H5: =E5*F5 -> 250 | J5: East | K5: =SUMIF(C4:C73, "East", (E4:E73)) -> 361 | L5: =SUMIF(C2:C71, "East", H2:H71) -> 5306
A6: 4005 | B6: Ankit Jain | C6: North | D6: Pencil | E6: 30 | F6: 5 | G6: 45413 | H6: =E6*F6 -> 150 | J6: West | K6: =SUMIF(C5:C74, "West", (E5:E74)) -> 346 | L6: =SUMIF(C2:C71, "West", H2:H71) -> 5519
A7: 4006 | B7: Sneha Patel | C7: South | D7: Notebook | E7: 12 | F7: 50 | G7: 45444 | H7: =E7*F7 -> 600
A8: 4007 | B8: Vikas Gupta | C8: East | D8: Eraser | E8: 25 | F8: 8 | G8: 45474 | H8: =E8*F8 -> 200
A9: 4008 | B9: Meera Nair | C9: West | D9: Pen | E9: 18 | F9: 10 | G9: 45505 | H9: =E9*F9 -> 180
A10: 4009 | B10: Anjali Rao | C10: North | D10: Marker | E10: 22 | F10: 25 | G10: 45536 | H10: =E10*F10 -> 550
A11: 4010 | B11: Manoj Das | C11: South | D11: Notebook | E11: 8 | F11: 50 | G11: 45566 | H11: =E11*F11 -> 400
A12: 4011 | B12: Ritika Sen | C12: East | D12: Pencil | E12: 40 | F12: 5 | G12: 45597 | H12: =E12*F12 -> 200
A13: 4012 | B13: Karan Malhotra | C13: West | D13: Eraser | E13: 35 | F13: 8 | G13: 45627 | H13: =E13*F13 -> 280
A14: 4013 | B14: Aryan Joshi | C14: North | D14: Notebook | E14: 14 | F14: 50 | G14: 13-01-2024 | H14: =E14*F14 -> 700
A15: 4014 | B15: Divya Kapoor | C15: South | D15: Pen | E15: 28 | F15: 10 | G15: 14-01-2024 | H15: =E15*F15 -> 280
A16: 4015 | B16: Sahil Arora | C16: East | D16: Marker | E16: 12 | F16: 25 | G16: 15-01-2024 | H16: =E16*F16 -> 300
A17: 4016 | B17: Muskan Jain | C17: West | D17: Pencil | E17: 25 | F17: 5 | G17: 16-01-2024 | H17: =E17*F17 -> 125
A18: 4017 | B18: Rohan Gupta | C18: North | D18: Eraser | E18: 20 | F18: 8 | G18: 17-01-2024 | H18: =E18*F18 -> 160
A19: 4018 | B19: Nidhi Sharma | C19: South | D19: Notebook | E19: 10 | F19: 50 | G19: 18-01-2024 | H19: =E19*F19 -> 500
A20: 4019 | B20: Tarun Verma | C20: East | D20: Pen | E20: 15 | F20: 10 | G20: 19-01-2024 | H20: =E20*F20 -> 150
A21: 4020 | B21: Simran Kaur | C21: West | D21: Marker | E21: 18 | F21: 25 | G21: 20-01-2024 | H21: =E21*F21 -> 450
A22: 4021 | B22: Deepak Rao | C22: North | D22: Notebook | E22: 9 | F22: 50 | G22: 21-01-2024 | H22: =E22*F22 -> 450
A23: 4022 | B23: Payal Mehta | C23: South | D23: Pencil | E23: 35 | F23: 5 | G23: 22-01-2024 | H23: =E23*F23 -> 175
A24: 4023 | B24: Aditya Singh | C24: East | D24: Eraser | E24: 30 | F24: 8 | G24: 23-01-2024 | H24: =E24*F24 -> 240
A25: 4024 | B25: Shreya Nair | C25: West | D25: Notebook | E25: 11 | F25: 50 | G25: 24-01-2024 | H25: =E25*F25 -> 550
... A32: 4031 | B32: Harsh Yadav | C32: East | D32: Marker | E32: 10 | F32: 25 | G32: 31-01-2024 | H32: =E32*F32 -> 250
A33: 4032 | B33: Kajal Rani | C33: West | D33: Pencil | E33: 18 | F33: 5 | G33: 45293 | H33: =E33*F33 -> 90
A34: 4033 | B34: Varun Sharma | C34: North | D34: Eraser | E34: 22 | F34: 8 | G34: 45324 | H34: =E34*F34 -> 176
A35: 4034 | B35: Swati Arora | C35: South | D35: Notebook | E35: 17 | F35: 50 | G35: 45353 | H35: =E35*F35 -> 850
A36: 4035 | B36: Akhil Jain | C36: East | D36: Pen | E36: 19 | F36: 10 | G36: 45384 | H36: =E36*F36 -> 190
A37: 4036 | B37: Priyanka Das | C37: West | D37: Marker | E37: 15 | F37: 25 | G37: 45414 | H37: =E37*F37 -> 375
A38: 4037 | B38: Ravi Nair | C38: North | D38: Pencil | E38: 28 | F38: 5 | G38: 45445 | H38: =E38*F38 -> 140
A39: 4038 | B39: Komal Singh | C39: South | D39: Eraser | E39: 24 | F39: 8 | G39: 45475 | H39: =E39*F39 -> 192
A40: 4039 | B40: Ayesha Khan | C40: East | D40: Notebook | E40: 16 | F40: 50 | G40: 45506 | H40: =E40*F40 -> 800
A41: 4040 | B41: Arjun Mehta | C41: West | D41: Pen | E41: 27 | F41: 10 | G41: 45537 | H41: =E41*F41 -> 270
A42: 4041 | B42: Sonali Gupta | C42: North | D42: Marker | E42: 21 | F42: 25 | G42: 45567 | H42: =E42*F42 -> 525
A43: 4042 | B43: Neeraj Kapoor | C43: South | D43: Pencil | E43: 30 | F43: 5 | G43: 45598 | H43: =E43*F43 -> 150
A44: 4043 | B44: Shruti Sharma | C44: East | D44: Eraser | E44: 26 | F44: 8 | G44: 45628 | H44: =E44*F44 -> 208
A45: 4044 | B45: Yash Arora | C45: West | D45: Notebook | E45: 14 | F45: 50 | G45: 13-02-2024 | H45: =E45*F45 -> 700
A46: 4045 | B46: Manish Das | C46: North | D46: Pen | E46: 20 | F46: 10 | G46: 14-02-2024 | H46: =E46*F46 -> 200
...

Sheet Task 8 Identify Extreme Values
A1: OrderID | B1: CustomerName | C1: Region | D1: Product | E1: Quantity | F1: UnitPrice | G1: OrderDate | H1: Total Sales
A2: 4001 | B2: Amit Sharma | C2: North | D2: Notebook | E2: 10 | F2: 50 | G2: 45292 | H2: =E2*F2 -> 500 | K2: Identifying the Extreme Values | L2: Amount | M2: Order ID
A3: 4002 | B3: Neha Verma | C3: South | D3: Pen | E3: 20 | F3: 10 | G3: 45323 | H3: =E3*F3 -> 200 | K3: Order with Highest Total Sales | L3: =MAX(H2:H71) -> 1000 | M3: =_xlfn.XLOOKUP(MAX(H2:H71), H2:H71,A2:A71) -> 4057
A4: 4003 | B4: Rahul Singh | C4: East | D4: Marker | E4: 15 | F4: 25 | G4: 45352 | H4: =E4*F4 -> 375 | K4: Order with Lowest Total Sales | L4: =MIN(H2:H71) -> 90 | M4: =_xlfn.XLOOKUP(MIN(H2:H71),H2:H71,A2:A71) -> 4032
A5: 4004 | B5: Pooja Mehta | C5: West | D5: Notebook | E5: 5 | F5: 50 | G5: 45383 | H5: =E5*F5 -> 250
A6: 4005 | B6: Ankit Jain | C6: North | D6: Pencil | E6: 30 | F6: 5 | G6: 45413 | H6: =E6*F6 -> 150
A7: 4006 | B7: Sneha Patel | C7: South | D7: Notebook | E7: 12 | F7: 50 | G7: 45444 | H7: =E7*F7 -> 600
A8: 4007 | B8: Vikas Gupta | C8: East | D8: Eraser | E8: 25 | F8: 8 | G8: 45474 | H8: =E8*F8 -> 200
A9: 4008 | B9: Meera Nair | C9: West | D9: Pen | E9: 18 | F9: 10 | G9: 45505 | H9: =E9*F9 -> 180
A10: 4009 | B10: Anjali Rao | C10: North | D10: Marker | E10: 22 | F10: 25 | G10: 45536 | H10: =E10*F10 -> 550
A11: 4010 | B11: Manoj Das | C11: South | D11: Notebook | E11: 8 | F11: 50 | G11: 45566 | H11: =E11*F11 -> 400
A12: 4011 | B12: Ritika Sen | C12: East | D12: Pencil | E12: 40 | F12: 5 | G12: 45597 | H12: =E12*F12 -> 200
A13: 4012 | B13: Karan Malhotra | C13: West | D13: Eraser | E13: 35 | F13: 8 | G13: 45627 | H13: =E13*F13 -> 280
A14: 4013 | B14: Aryan Joshi | C14: North | D14: Notebook | E14: 14 | F14: 50 | G14: 13-01-2024 | H14: =E14*F14 -> 700
A15: 4014 | B15: Divya Kapoor | C15: South | D15: Pen | E15: 28 | F15: 10 | G15: 14-01-2024 | H15: =E15*F15 -> 280
A16: 4015 | B16: Sahil Arora | C16: East | D16: Marker | E16: 12 | F16: 25 | G16: 15-01-2024 | H16: =E16*F16 -> 300
A17: 4016 | B17: Muskan Jain | C17: West | D17: Pencil | E17: 25 | F17: 5 | G17: 16-01-2024 | H17: =E17*F17 -> 125
A18: 4017 | B18: Rohan Gupta | C18: North | D18: Eraser | E18: 20 | F18: 8 | G18: 17-01-2024 | H18: =E18*F18 -> 160
A19: 4018 | B19: Nidhi Sharma | C19: South | D19: Notebook | E19: 10 | F19: 50 | G19: 18-01-2024 | H19: =E19*F19 -> 500
A20: 4019 | B20: Tarun Verma | C20: East | D20: Pen | E20: 15 | F20: 10 | G20: 19-01-2024 | H20: =E20*F20 -> 150
A21: 4020 | B21: Simran Kaur | C21: West | D21: Marker | E21: 18 | F21: 25 | G21: 20-01-2024 | H21: =E21*F21 -> 450
A22: 4021 | B22: Deepak Rao | C22: North | D22: Notebook | E22: 9 | F22: 50 | G22: 21-01-2024 | H22: =E22*F22 -> 450
A23: 4022 | B23: Payal Mehta | C23: South | D23: Pencil | E23: 35 | F23: 5 | G23: 22-01-2024 | H23: =E23*F23 -> 175
A24: 4023 | B24: Aditya Singh | C24: East | D24: Eraser | E24: 30 | F24: 8 | G24: 23-01-2024 | H24: =E24*F24 -> 240
A25: 4024 | B25: Shreya Nair | C25: West | D25: Notebook | E25: 11 | F25: 50 | G25: 24-01-2024 | H25: =E25*F25 -> 550
... A32: 4031 | B32: Harsh Yadav | C32: East | D32: Marker | E32: 10 | F32: 25 | G32: 31-01-2024 | H32: =E32*F32 -> 250
A33: 4032 | B33: Kajal Rani | C33: West | D33: Pencil | E33: 18 | F33: 5 | G33: 45293 | H33: =E33*F33 -> 90
A34: 4033 | B34: Varun Sharma | C34: North | D34: Eraser | E34: 22 | F34: 8 | G34: 45324 | H34: =E34*F34 -> 176
A35: 4034 | B35: Swati Arora | C35: South | D35: Notebook | E35: 17 | F35: 50 | G35: 45353 | H35: =E35*F35 -> 850
A36: 4035 | B36: Akhil Jain | C36: East | D36: Pen | E36: 19 | F36: 10 | G36: 45384 | H36: =E36*F36 -> 190
A37: 4036 | B37: Priyanka Das | C37: West | D37: Marker | E37: 15 | F37: 25 | G37: 45414 | H37: =E37*F37 -> 375
A38: 4037 | B38: Ravi Nair | C38: North | D38: Pencil | E38: 28 | F38: 5 | G38: 45445 | H38: =E38*F38 -> 140
A39: 4038 | B39: Komal Singh | C39: South | D39: Eraser | E39: 24 | F39: 8 | G39: 45475 | H39: =E39*F39 -> 192
A40: 4039 | B40: Ayesha Khan | C40: East | D40: Notebook | E40: 16 | F40: 50 | G40: 45506 | H40: =E40*F40 -> 800
A41: 4040 | B41: Arjun Mehta | C41: West | D41: Pen | E41: 27 | F41: 10 | G41: 45537 | H41: =E41*F41 -> 270
A42: 4041 | B42: Sonali Gupta | C42: North | D42: Marker | E42: 21 | F42: 25 | G42: 45567 | H42: =E42*F42 -> 525
A43: 4042 | B43: Neeraj Kapoor | C43: South | D43: Pencil | E43: 30 | F43: 5 | G43: 45598 | H43: =E43*F43 -> 150
A44: 4043 | B44: Shruti Sharma | C44: East | D44: Eraser | E44: 26 | F44: 8 | G44: 45628 | H44: =E44*F44 -> 208
A45: 4044 | B45: Yash Arora | C45: West | D45: Notebook | E45: 14 | F45: 50 | G45: 13-02-2024 | H45: =E45*F45 -> 700
A46: 4045 | B46: Manish Das | C46: North | D46: Pen | E46: 20 | F46: 10 | G46: 14-02-2024 | H46: =E46*F46 -> 200
...

Sheet Task 9 Top Order
A1: OrderID | B1: CustomerName | C1: Region | D1: Product | E1: Quantity | F1: UnitPrice | G1: OrderDate | H1: Total Sales
A2: 4057 | B2: Vikas Gupta | C2: East | D2: Notebook | E2: 20 | F2: 50 | G2: 26-02-2024 | H2: =E2*F2 -> 1000 | J2: Extract top 10 orders
A3: 4066 | B3: Muskan Jain | C3: West | D3: Notebook | E3: 18 | F3: 50 | G3: 45446 | H3: =E3*F3 -> 900
A4: 4034 | B4: Swati Arora | C4: South | D4: Notebook | E4: 17 | F4: 50 | G4: 45353 | H4: =E4*F4 -> 850
A5: 4039 | B5: Ayesha Khan | C5: East | D5: Notebook | E5: 16 | F5: 50 | G5: 45506 | H5: =E5*F5 -> 800
A6: 4013 | B6: Aryan Joshi | C6: North | D6: Notebook | E6: 14 | F6: 50 | G6: 13-01-2024 | H6: =E6*F6 -> 700
A7: 4044 | B7: Yash Arora | C7: West | D7: Notebook | E7: 14 | F7: 50 | G7: 13-02-2024 | H7: =E7*F7 -> 700
A8: 4052 | B8: Neha Verma | C8: South | D8: Notebook | E8: 14 | F8: 50 | G8: 21-02-2024 | H8: =E8*F8 -> 700
A9: 4029 | B9: Anurag Mishra | C9: North | D9: Notebook | E9: 13 | F9: 50 | G9: 29-01-2024 | H9: =E9*F9 -> 650
A10: 4006 | B10: Sneha Patel | C10: South | D10: Notebook | E10: 12 | F10: 50 | G10: 45444 | H10: =E10*F10 -> 600
A11: 4049 | B11: Ritika Jain | C11: North | D11: Notebook | E11: 12 | F11: 50 | G11: 18-02-2024 | H11: =E11*F11 -> 600
A12: 4061 | B12: Ritika Sen | C12: East | D12: Notebook | E12: 12 | F12: 50 | G12: 45294 | H12: =E12*F12 -> 600

Sheet Task 10 Final Report Sheet
A1: OrderID | B1: CustomerName | C1: Region | D1: Product | E1: Quantity | F1: UnitPrice | G1: OrderDate | H1: Total Sales
A2: 4001 | B2: Amit Sharma | C2: North | D2: Notebook | E2: 10 | F2: 50 | G2: 45292 | H2: =E2*F2 -> 500 | K2: Final Report
A3: 4002 | B3: Neha Verma | C3: South | D3: Pen | E3: 20 | F3: 10 | G3: 45323 | H3: =E3*F3 -> 200 | K3: Total Sales | L3: =SUM(H2:H71) -> 23582
A4: 4003 | B4: Rahul Singh | C4: East | D4: Marker | E4: 15 | F4: 25 | G4: 45352 | H4: =E4*F4 -> 375 | K4: Average Sales | L4: =AVERAGE(H2:H71) -> 336.88571
A5: 4004 | B5: Pooja Mehta | C5: West | D5: Notebook | E5: 5 | F5: 50 | G5: 45383 | H5: =E5*F5 -> 250 | K5: Total Orders | L5: =SUM(E2:E71) -> 1430
A6: 4005 | B6: Ankit Jain | C6: North | D6: Pencil | E6: 30 | F6: 5 | G6: 45413 | H6: =E6*F6 -> 150 | K6: Highest Sale | L6: =MAX(H2:H71) -> 1000
A7: 4006 | B7: Sneha Patel | C7: South | D7: Notebook | E7: 12 | F7: 50 | G7: 45444 | H7: =E7*F7 -> 600 | K7: Lowest Sale | L7: =MIN(H2:H71) -> 90
A8: 4007 | B8: Vikas Gupta | C8: East | D8: Eraser | E8: 25 | F8: 8 | G8: 45474 | H8: =E8*F8 -> 200
A9: 4008 | B9: Meera Nair | C9: West | D9: Pen | E9: 18 | F9: 10 | G9: 45505 | H9: =E9*F9 -> 180
A10: 4009 | B10: Anjali Rao | C10: North | D10: Marker | E10: 22 | F10: 25 | G10: 45536 | H10: =E10*F10 -> 550
A11: 4010 | B11: Manoj Das | C11: South | D11: Notebook | E11: 8 | F11: 50 | G11: 45566 | H11: =E11*F11 -> 400
A12: 4011 | B12: Ritika Sen | C12: East | D12: Pencil | E12: 40 | F12: 5 | G12: 45597 | H12: =E12*F12 -> 200
A13: 4012 | B13: Karan Malhotra | C13: West | D13: Eraser | E13: 35 | F13: 8 | G13: 45627 | H13: =E13*F13 -> 280
A14: 4013 | B14: Aryan Joshi | C14: North | D14: Notebook | E14: 14 | F14: 50 | G14: 13-01-2024 | H14: =E14*F14 -> 700
A15: 4014 | B15: Divya Kapoor | C15: South | D15: Pen | E15: 28 | F15: 10 | G15: 14-01-2024 | H15: =E15*F15 -> 280
A16: 4015 | B16: Sahil Arora | C16: East | D16: Marker | E16: 12 | F16: 25 | G16: 15-01-2024 | H16: =E16*F16 -> 300
A17: 4016 | B17: Muskan Jain | C17: West | D17: Pencil | E17: 25 | F17: 5 | G17: 16-01-2024 | H17: =E17*F17 -> 125
A18: 4017 | B18: Rohan Gupta | C18: North | D18: Eraser | E18: 20 | F18: 8 | G18: 17-01-2024 | H18: =E18*F18 -> 160
A19: 4018 | B19: Nidhi Sharma | C19: South | D19: Notebook | E19: 10 | F19: 50 | G19: 18-01-2024 | H19: =E19*F19 -> 500
A20: 4019 | B20: Tarun Verma | C20: East | D20: Pen | E20: 15 | F20: 10 | G20: 19-01-2024 | H20: =E20*F20 -> 150
A21: 4020 | B21: Simran Kaur | C21: West | D21: Marker | E21: 18 | F21: 25 | G21: 20-01-2024 | H21: =E21*F21 -> 450
A22: 4021 | B22: Deepak Rao | C22: North | D22: Notebook | E22: 9 | F22: 50 | G22: 21-01-2024 | H22: =E22*F22 -> 450
A23: 4022 | B23: Payal Mehta | C23: South | D23: Pencil | E23: 35 | F23: 5 | G23: 22-01-2024 | H23: =E23*F23 -> 175
A24: 4023 | B24: Aditya Singh | C24: East | D24: Eraser | E24: 30 | F24: 8 | G24: 23-01-2024 | H24: =E24*F24 -> 240
A25: 4024 | B25: Shreya Nair | C25: West | D25: Notebook | E25: 11 | F25: 50 | G25: 24-01-2024 | H25: =E25*F25 -> 550
... A32: 4031 | B32: Harsh Yadav | C32: East | D32: Marker | E32: 10 | F32: 25 | G32: 31-01-2024 | H32: =E32*F32 -> 250
A33: 4032 | B33: Kajal Rani | C33: West | D33: Pencil | E33: 18 | F33: 5 | G33: 45293 | H33: =E33*F33 -> 90
A34: 4033 | B34: Varun Sharma | C34: North | D34: Eraser | E34: 22 | F34: 8 | G34: 45324 | H34: =E34*F34 -> 176
A35: 4034 | B35: Swati Arora | C35: South | D35: Notebook | E35: 17 | F35: 50 | G35: 45353 | H35: =E35*F35 -> 850
A36: 4035 | B36: Akhil Jain | C36: East | D36: Pen | E36: 19 | F36: 10 | G36: 45384 | H36: =E36*F36 -> 190
A37: 4036 | B37: Priyanka Das | C37: West | D37: Marker | E37: 15 | F37: 25 | G37: 45414 | H37: =E37*F37 -> 375
A38: 4037 | B38: Ravi Nair | C38: North | D38: Pencil | E38: 28 | F38: 5 | G38: 45445 | H38: =E38*F38 -> 140
A39: 4038 | B39: Komal Singh | C39: South | D39: Eraser | E39: 24 | F39: 8 | G39: 45475 | H39: =E39*F39 -> 192
A40: 4039 | B40: Ayesha Khan | C40: East | D40: Notebook | E40: 16 | F40: 50 | G40: 45506 | H40: =E40*F40 -> 800
A41: 4040 | B41: Arjun Mehta | C41: West | D41: Pen | E41: 27 | F41: 10 | G41: 45537 | H41: =E41*F41 -> 270
A42: 4041 | B42: Sonali Gupta | C42: North | D42: Marker | E42: 21 | F42: 25 | G42: 45567 | H42: =E42*F42 -> 525
A43: 4042 | B43: Neeraj Kapoor | C43: South | D43: Pencil | E43: 30 | F43: 5 | G43: 45598 | H43: =E43*F43 -> 150
A44: 4043 | B44: Shruti Sharma | C44: East | D44: Eraser | E44: 26 | F44: 8 | G44: 45628 | H44: =E44*F44 -> 208
A45: 4044 | B45: Yash Arora | C45: West | D45: Notebook | E45: 14 | F45: 50 | G45: 13-02-2024 | H45: =E45*F45 -> 700
A46: 4045 | B46: Manish Das | C46: North | D46: Pen | E46: 20 | F46: 10 | G46: 14-02-2024 | H46: =E46*F46 -> 200
...
